<?xml version="1.0" encoding="utf-8"?>
<!-- This URDF was automatically created by SolidWorks to URDF Exporter! Originally created by Stephen Brawner (brawner@gmail.com) 
     Commit Version: 1.5.1-0-g916b5db  Build Version: 1.5.7152.31018
     For more information, please see http://wiki.ros.org/sw_urdf_exporter -->
<robot
  name="spryped rev03">
  <link
    name="body">
    <inertial>
      <origin
        xyz="0.0014668 -0.047188 0.07617"
        rpy="0 0 0" />
      <mass
        value="3.7031" />
      <inertia
        ixx="0.0042957"
        ixy="3.0328E-09"
        ixz="-2.3333E-06"
        iyy="0.0033547"
        iyz="-8.3206E-06"
        izz="0.0059126" />
    </inertial>
    <visual>
      <origin
        xyz="0 0 0"
        rpy="0 0 0" />
      <geometry>
        <mesh
          filename="package://spryped rev03/meshes/body.STL" />
      </geometry>
      <material
        name="">
        <color
          rgba="1 1 1 1" />
      </material>
    </visual>
    <collision>
      <origin
        xyz="0 0 0"
        rpy="0 0 0" />
      <geometry>
        <mesh
          filename="package://spryped rev03/meshes/body.STL" />
      </geometry>
    </collision>
  </link>
  <link
    name="left femur">
    <inertial>
      <origin
        xyz="0.0014637 0.050952 -0.056842"
        rpy="0 0 0" />
      <mass
        value="0.30999" />
      <inertia
        ixx="0.00069104"
        ixy="-9.483E-08"
        ixz="3.5642E-05"
        iyy="0.00070116"
        iyz="3.5726E-05"
        izz="0.00059024" />
    </inertial>
    <visual>
      <origin
        xyz="0 0 0"
        rpy="0 0 0" />
      <geometry>
        <mesh
          filename="package://spryped rev03/meshes/left femur.STL" />
      </geometry>
      <material
        name="">
        <color
          rgba="1 1 1 1" />
      </material>
    </visual>
    <collision>
      <origin
        xyz="0 0 0"
        rpy="0 0 0" />
      <geometry>
        <mesh
          filename="package://spryped rev03/meshes/left femur.STL" />
      </geometry>
    </collision>
  </link>
  <joint
    name="1"
    type="revolute">
    <origin
      xyz="0.145467828474498 -0.103472193336681 0.055903737730272"
      rpy="0 0 0" />
    <parent
      link="body" />
    <child
      link="left femur" />
    <axis
      xyz="0 -1 0" />
    <limit
      lower="-1.57."
      upper="1.57."
      effort="0"
      velocity="1000" />
  </joint>
  <link
    name="left tibiotarsus">
    <inertial>
      <origin
        xyz="0.049213 0.053539 -0.084279"
        rpy="0 0 0" />
      <mass
        value="2.8777" />
      <inertia
        ixx="0.0053353"
        ixy="7.3556E-08"
        ixz="-1.1074E-07"
        iyy="0.003496"
        iyz="0.0014827"
        izz="0.0022585" />
    </inertial>
    <visual>
      <origin
        xyz="0 0 0"
        rpy="0 0 0" />
      <geometry>
        <mesh
          filename="package://spryped rev03/meshes/left tibiotarsus.STL" />
      </geometry>
      <material
        name="">
        <color
          rgba="1 1 1 1" />
      </material>
    </visual>
    <collision>
      <origin
        xyz="0 0 0"
        rpy="0 0 0" />
      <geometry>
        <mesh
          filename="package://spryped rev03/meshes/left tibiotarsus.STL" />
      </geometry>
    </collision>
  </link>
  <joint
    name="2"
    type="revolute">
    <origin
      xyz="-0.0496499999999997 0.0516500000000001 -0.114"
      rpy="0 0 0" />
    <parent
      link="left femur" />
    <child
      link="left tibiotarsus" />
    <axis
      xyz="-1 0 0" />
    <limit
      lower="-1.57."
      upper="1.57."
      effort="0"
      velocity="1000" />
  </joint>
  <link
    name="left tarsometatarsus">
    <inertial>
      <origin
        xyz="0.065339 0.0041021 -0.10795"
        rpy="0 0 0" />
      <mass
        value="0.38643" />
      <inertia
        ixx="0.0015965"
        ixy="3.4483E-05"
        ixz="-3.1686E-05"
        iyy="0.00151"
        iyz="-0.00031081"
        izz="0.00055388" />
    </inertial>
    <visual>
      <origin
        xyz="0 0 0"
        rpy="0 0 0" />
      <geometry>
        <mesh
          filename="package://spryped rev03/meshes/left tarsometatarsus.STL" />
      </geometry>
      <material
        name="">
        <color
          rgba="1 1 1 1" />
      </material>
    </visual>
    <collision>
      <origin
        xyz="0 0 0"
        rpy="0 0 0" />
      <geometry>
        <mesh
          filename="package://spryped rev03/meshes/left tarsometatarsus.STL" />
      </geometry>
    </collision>
  </link>
  <joint
    name="3"
    type="revolute">
    <origin
      xyz="-0.000500000000000944 0.105453933582409 -0.168761571135128"
      rpy="0 0 0" />
    <parent
      link="left tibiotarsus" />
    <child
      link="left tarsometatarsus" />
    <axis
      xyz="-1 0 0" />
    <limit
      lower="-1.57."
      upper="1.57."
      effort="0"
      velocity="1000" />
  </joint>
  <link
    name="left toe">
    <inertial>
      <origin
        xyz="0.0055 0.024654 -0.037699"
        rpy="0 0 0" />
      <mass
        value="0.11189" />
      <inertia
        ixx="0.00021756"
        ixy="-7.6214E-13"
        ixz="8.8251E-14"
        iyy="3.2605E-05"
        iyz="-1.9901E-06"
        izz="0.00019521" />
    </inertial>
    <visual>
      <origin
        xyz="0 0 0"
        rpy="0 0 0" />
      <geometry>
        <mesh
          filename="package://spryped rev03/meshes/left toe.STL" />
      </geometry>
      <material
        name="">
        <color
          rgba="1 1 1 1" />
      </material>
    </visual>
    <collision>
      <origin
        xyz="0 0 0"
        rpy="0 0 0" />
      <geometry>
        <mesh
          filename="package://spryped rev03/meshes/left toe.STL" />
      </geometry>
    </collision>
  </link>
  <joint
    name="4"
    type="revolute">
    <origin
      xyz="0.0444000000000008 -0.122958145890606 -0.482725854452568"
      rpy="0 0 0" />
    <parent
      link="left tarsometatarsus" />
    <child
      link="left toe" />
    <axis
      xyz="-1 0 0" />
    <limit
      lower="-1.57."
      upper="1.57."
      effort="0"
      velocity="1000" />
  </joint>
  <link
    name="right femur">
    <inertial>
      <origin
        xyz="-0.0014638 0.050952 -0.056842"
        rpy="0 0 0" />
      <mass
        value="0.30999" />
      <inertia
        ixx="0.00069104"
        ixy="9.5179E-08"
        ixz="-3.5642E-05"
        iyy="0.00070116"
        iyz="3.5726E-05"
        izz="0.00059025" />
    </inertial>
    <visual>
      <origin
        xyz="0 0 0"
        rpy="0 0 0" />
      <geometry>
        <mesh
          filename="package://spryped rev03/meshes/right femur.STL" />
      </geometry>
      <material
        name="">
        <color
          rgba="1 1 1 1" />
      </material>
    </visual>
    <collision>
      <origin
        xyz="0 0 0"
        rpy="0 0 0" />
      <geometry>
        <mesh
          filename="package://spryped rev03/meshes/right femur.STL" />
      </geometry>
    </collision>
  </link>
  <joint
    name="5"
    type="revolute">
    <origin
      xyz="-0.1425321715255 -0.103472193336681 0.0559037377302649"
      rpy="0 0 0" />
    <parent
      link="body" />
    <child
      link="right femur" />
    <axis
      xyz="0 -1 0" />
    <limit
      lower="-1.57."
      upper="1.57."
      effort="0"
      velocity="1000" />
  </joint>
  <link
    name="right tibiotarsus">
    <inertial>
      <origin
        xyz="-0.049249 0.053502 -0.084231"
        rpy="0 0 0" />
      <mass
        value="2.8758" />
      <inertia
        ixx="0.0053353"
        ixy="-7.128E-08"
        ixz="1.2222E-07"
        iyy="0.0034959"
        iyz="0.0014827"
        izz="0.0022585" />
    </inertial>
    <visual>
      <origin
        xyz="0 0 0"
        rpy="0 0 0" />
      <geometry>
        <mesh
          filename="package://spryped rev03/meshes/right tibiotarsus.STL" />
      </geometry>
      <material
        name="">
        <color
          rgba="1 1 1 1" />
      </material>
    </visual>
    <collision>
      <origin
        xyz="0 0 0"
        rpy="0 0 0" />
      <geometry>
        <mesh
          filename="package://spryped rev03/meshes/right tibiotarsus.STL" />
      </geometry>
    </collision>
  </link>
  <joint
    name="6"
    type="revolute">
    <origin
      xyz="0.04965 0.0516500000000001 -0.114"
      rpy="0 0 0" />
    <parent
      link="right femur" />
    <child
      link="right tibiotarsus" />
    <axis
      xyz="1 0 0" />
    <limit
      lower="-1.57."
      upper="1.57."
      effort="0"
      velocity="1000" />
  </joint>
  <link
    name="right tarsometatarsus">
    <inertial>
      <origin
        xyz="-0.065487 0.0044219 -0.10734"
        rpy="0 0 0" />
      <mass
        value="0.38839" />
      <inertia
        ixx="0.0015965"
        ixy="-3.4579E-05"
        ixz="3.1581E-05"
        iyy="0.001512"
        iyz="-0.00030783"
        izz="0.00055199" />
    </inertial>
    <visual>
      <origin
        xyz="0 0 0"
        rpy="0 0 0" />
      <geometry>
        <mesh
          filename="package://spryped rev03/meshes/right tarsometatarsus.STL" />
      </geometry>
      <material
        name="">
        <color
          rgba="1 1 1 1" />
      </material>
    </visual>
    <collision>
      <origin
        xyz="0 0 0"
        rpy="0 0 0" />
      <geometry>
        <mesh
          filename="package://spryped rev03/meshes/right tarsometatarsus.STL" />
      </geometry>
    </collision>
  </link>
  <joint
    name="7"
    type="revolute">
    <origin
      xyz="0.000500000000003886 0.105453933582128 -0.168761571135296"
      rpy="0 0 0" />
    <parent
      link="right tibiotarsus" />
    <child
      link="right tarsometatarsus" />
    <axis
      xyz="1 0 0" />
    <limit
      lower="-1.57."
      upper="1.57."
      effort="0"
      velocity="1000" />
  </joint>
  <link
    name="right toe">
    <inertial>
      <origin
        xyz="-0.016 0.0086389 -0.031995"
        rpy="0 0 0" />
      <mass
        value="0.11189" />
      <inertia
        ixx="0.00021756"
        ixy="-7.6214E-13"
        ixz="8.8251E-14"
        iyy="3.2605E-05"
        iyz="-1.9901E-06"
        izz="0.00019521" />
    </inertial>
    <visual>
      <origin
        xyz="0 0 0"
        rpy="0 0 0" />
      <geometry>
        <mesh
          filename="package://spryped rev03/meshes/right toe.STL" />
      </geometry>
      <material
        name="">
        <color
          rgba="1 1 1 1" />
      </material>
    </visual>
    <collision>
      <origin
        xyz="0 0 0"
        rpy="0 0 0" />
      <geometry>
        <mesh
          filename="package://spryped rev03/meshes/right toe.STL" />
      </geometry>
    </collision>
  </link>
  <joint
    name="8"
    type="revolute">
    <origin
      xyz="-0.0339000000000053 -0.105453933613821 -0.488752972251687"
      rpy="0 0 0" />
    <parent
      link="right tarsometatarsus" />
    <child
      link="right toe" />
    <axis
      xyz="-1 0 0" />
    <limit
      lower="-1.57."
      upper="1.57."
      effort="0"
      velocity="1000" />
  </joint>
</robot>
