<?xml version="1.0" encoding="utf-8"?>
<!-- This URDF was automatically created by SolidWorks to URDF Exporter! Originally created by Stephen Brawner (brawner@gmail.com) 
     Commit Version: 1.5.1-0-g916b5db  Build Version: 1.5.7152.31018
     For more information, please see http://wiki.ros.org/sw_urdf_exporter -->
<robot
  name="spryped_urdf_rev05">
  <link
    name="body">
    <inertial>
      <origin
        xyz="0.047188 -1.437E-06 0.07617"
        rpy="0 0 0" />
      <mass
        value="3.7031" />
      <inertia
        ixx="0.0033547"
        ixy="-2.8419E-09"
        ixz="8.3206E-06"
        iyy="0.0042957"
        iyz="-2.3334E-06"
        izz="0.0059126" />
    </inertial>
    <visual>
      <origin
        xyz="0 0 0"
        rpy="0 0 0" />
      <geometry>
        <mesh
          filename="package://spryped_urdf_rev05/meshes/body.STL" />
      </geometry>
      <material
        name="">
        <color
          rgba="1 1 1 1" />
      </material>
    </visual>
    <collision>
      <origin
        xyz="0 0 0"
        rpy="0 0 0" />
      <geometry>
        <mesh
          filename="package://spryped_urdf_rev05/meshes/body.STL" />
      </geometry>
    </collision>
  </link>
  <link
    name="left femur">
    <inertial>
      <origin
        xyz="-0.050952 0.0014637 -0.056842"
        rpy="0 0 0" />
      <mass
        value="0.30999" />
      <inertia
        ixx="0.00070116"
        ixy="9.483E-08"
        ixz="-3.5726E-05"
        iyy="0.00069104"
        iyz="3.5642E-05"
        izz="0.00059024" />
    </inertial>
    <visual>
      <origin
        xyz="0 0 0"
        rpy="0 0 0" />
      <geometry>
        <mesh
          filename="package://spryped_urdf_rev05/meshes/left femur.STL" />
      </geometry>
      <material
        name="">
        <color
          rgba="1 1 1 1" />
      </material>
    </visual>
    <collision>
      <origin
        xyz="0 0 0"
        rpy="0 0 0" />
      <geometry>
        <mesh
          filename="package://spryped_urdf_rev05/meshes/left femur.STL" />
      </geometry>
    </collision>
  </link>
  <joint
    name="1"
    type="revolute">
    <origin
      xyz="0.10347219333668 0.144 0.0559037377303131"
      rpy="0 0 0" />
    <parent
      link="body" />
    <child
      link="left femur" />
    <axis
      xyz="1 0 0" />
    <limit
      lower="-3.14"
      upper="3.14"
      effort="0"
      velocity="0" />
  </joint>
  <link
    name="left tibiotarsus">
    <inertial>
      <origin
        xyz="-0.053318 0.049182 -0.084109"
        rpy="0 0 0" />
      <mass
        value="2.8758" />
      <inertia
        ixx="0.0035003"
        ixy="-7.3489E-08"
        ixz="-0.0014845"
        iyy="0.0053353"
        iyz="-1.0934E-07"
        izz="0.0022541" />
    </inertial>
    <visual>
      <origin
        xyz="0 0 0"
        rpy="0 0 0" />
      <geometry>
        <mesh
          filename="package://spryped_urdf_rev05/meshes/left tibiotarsus.STL" />
      </geometry>
      <material
        name="">
        <color
          rgba="1 1 1 1" />
      </material>
    </visual>
    <collision>
      <origin
        xyz="0 0 0"
        rpy="0 0 0" />
      <geometry>
        <mesh
          filename="package://spryped_urdf_rev05/meshes/left tibiotarsus.STL" />
      </geometry>
    </collision>
  </link>
  <joint
    name="2"
    type="revolute">
    <origin
      xyz="-0.05165 -0.04965 -0.114"
      rpy="0 0 0" />
    <parent
      link="left femur" />
    <child
      link="left tibiotarsus" />
    <axis
      xyz="0 -1 0" />
    <limit
      lower="-3.14"
      upper="3.14"
      effort="0"
      velocity="0" />
  </joint>
  <link
    name="left tarsometatarsus">
    <inertial>
      <origin
        xyz="-0.003858 0.065488 -0.10614"
        rpy="0 0 0" />
      <mass
        value="0.38839" />
      <inertia
        ixx="0.0015068"
        ixy="-3.4483E-05"
        ixz="0.00031712"
        iyy="0.0015965"
        iyz="-3.1686E-05"
        izz="0.0005572" />
    </inertial>
    <visual>
      <origin
        xyz="0 0 0"
        rpy="0 0 0" />
      <geometry>
        <mesh
          filename="package://spryped_urdf_rev05/meshes/left tarsometatarsus.STL" />
      </geometry>
      <material
        name="">
        <color
          rgba="1 1 1 1" />
      </material>
    </visual>
    <collision>
      <origin
        xyz="0 0 0"
        rpy="0 0 0" />
      <geometry>
        <mesh
          filename="package://spryped_urdf_rev05/meshes/left tarsometatarsus.STL" />
      </geometry>
    </collision>
  </link>
  <joint
    name="3"
    type="revolute">
    <origin
      xyz="-0.10545393358234 -0.000500000000001388 -0.168761571135171"
      rpy="0 0 0" />
    <parent
      link="left tibiotarsus" />
    <child
      link="left tarsometatarsus" />
    <axis
      xyz="0 -1 0" />
    <limit
      lower="-3.14"
      upper="3.14"
      effort="0"
      velocity="0" />
  </joint>
  <link
    name="left toe">
    <inertial>
      <origin
        xyz="-0.0086389 0.016 -0.031995"
        rpy="0 0 0" />
      <mass
        value="0.11189" />
      <inertia
        ixx="3.2605E-05"
        ixy="7.6214E-13"
        ixz="1.9901E-06"
        iyy="0.00021756"
        iyz="8.8251E-14"
        izz="0.00019521" />
    </inertial>
    <visual>
      <origin
        xyz="0 0 0"
        rpy="0 0 0" />
      <geometry>
        <mesh
          filename="package://spryped_urdf_rev05/meshes/left toe.STL" />
      </geometry>
      <material
        name="">
        <color
          rgba="1 1 1 1" />
      </material>
    </visual>
    <collision>
      <origin
        xyz="0 0 0"
        rpy="0 0 0" />
      <geometry>
        <mesh
          filename="package://spryped_urdf_rev05/meshes/left toe.STL" />
      </geometry>
    </collision>
  </link>
  <joint
    name="4"
    type="revolute">
    <origin
      xyz="0.106943415565972 0.0339000000000015 -0.488429222986096"
      rpy="0 0 0" />
    <parent
      link="left tarsometatarsus" />
    <child
      link="left toe" />
    <axis
      xyz="0 -1 0" />
    <limit
      lower="-3.14"
      upper="3.14"
      effort="0"
      velocity="0" />
  </joint>
  <link
    name="right femur">
    <inertial>
      <origin
        xyz="-0.050952 -0.0014638 -0.056842"
        rpy="0 0 0" />
      <mass
        value="0.30999" />
      <inertia
        ixx="0.00070116"
        ixy="-9.5179E-08"
        ixz="-3.5726E-05"
        iyy="0.00069104"
        iyz="-3.5642E-05"
        izz="0.00059025" />
    </inertial>
    <visual>
      <origin
        xyz="0 0 0"
        rpy="0 0 0" />
      <geometry>
        <mesh
          filename="package://spryped_urdf_rev05/meshes/right femur.STL" />
      </geometry>
      <material
        name="">
        <color
          rgba="1 1 1 1" />
      </material>
    </visual>
    <collision>
      <origin
        xyz="0 0 0"
        rpy="0 0 0" />
      <geometry>
        <mesh
          filename="package://spryped_urdf_rev05/meshes/right femur.STL" />
      </geometry>
    </collision>
  </link>
  <joint
    name="5"
    type="revolute">
    <origin
      xyz="0.10347 -0.144 0.055904"
      rpy="0 0 0" />
    <parent
      link="body" />
    <child
      link="right femur" />
    <axis
      xyz="1 0 0" />
    <limit
      lower="-3.14"
      upper="3.14"
      effort="0"
      velocity="0" />
  </joint>
  <link
    name="right tibiotarsus">
    <inertial>
      <origin
        xyz="-0.053318 -0.049249 -0.084109"
        rpy="0 0 0" />
      <mass
        value="2.8758" />
      <inertia
        ixx="0.0035003"
        ixy="7.1452E-08"
        ixz="-0.0014845"
        iyy="0.0053353"
        iyz="1.2268E-07"
        izz="0.0022541" />
    </inertial>
    <visual>
      <origin
        xyz="0 0 0"
        rpy="0 0 0" />
      <geometry>
        <mesh
          filename="package://spryped_urdf_rev05/meshes/right tibiotarsus.STL" />
      </geometry>
      <material
        name="">
        <color
          rgba="1 1 1 1" />
      </material>
    </visual>
    <collision>
      <origin
        xyz="0 0 0"
        rpy="0 0 0" />
      <geometry>
        <mesh
          filename="package://spryped_urdf_rev05/meshes/right tibiotarsus.STL" />
      </geometry>
    </collision>
  </link>
  <joint
    name="6"
    type="revolute">
    <origin
      xyz="-0.0516500000000863 0.04965 -0.114"
      rpy="0 0 0" />
    <parent
      link="right femur" />
    <child
      link="right tibiotarsus" />
    <axis
      xyz="0 1 0" />
    <limit
      lower="-3.14"
      upper="3.14"
      effort="0"
      velocity="0" />
  </joint>
  <link
    name="right tarsometatarsus">
    <inertial>
      <origin
        xyz="-0.0041858 -0.065487 -0.10614"
        rpy="0 0 0" />
      <mass
        value="0.38839" />
      <inertia
        ixx="0.0015087"
        ixy="3.4579E-05"
        ixz="0.00031414"
        iyy="0.0015965"
        iyz="3.1581E-05"
        izz="0.00055526" />
    </inertial>
    <visual>
      <origin
        xyz="0 0 0"
        rpy="0 0 0" />
      <geometry>
        <mesh
          filename="package://spryped_urdf_rev05/meshes/right tarsometatarsus.STL" />
      </geometry>
      <material
        name="">
        <color
          rgba="1 1 1 1" />
      </material>
    </visual>
    <collision>
      <origin
        xyz="0 0 0"
        rpy="0 0 0" />
      <geometry>
        <mesh
          filename="package://spryped_urdf_rev05/meshes/right tarsometatarsus.STL" />
      </geometry>
    </collision>
  </link>
  <joint
    name="7"
    type="revolute">
    <origin
      xyz="-0.105453933582318 0.0005 -0.168761571135185"
      rpy="0 0 0" />
    <parent
      link="right tibiotarsus" />
    <child
      link="right tarsometatarsus" />
    <axis
      xyz="0 1 0" />
    <limit
      lower="-3.14"
      upper="3.14"
      effort="0"
      velocity="0" />
  </joint>
  <link
    name="right toe">
    <inertial>
      <origin
        xyz="-0.0086389 -0.016 -0.031995"
        rpy="0 0 0" />
      <mass
        value="0.11189" />
      <inertia
        ixx="3.2605E-05"
        ixy="7.6214E-13"
        ixz="1.9901E-06"
        iyy="0.00021756"
        iyz="8.8251E-14"
        izz="0.00019521" />
    </inertial>
    <visual>
      <origin
        xyz="0 0 0"
        rpy="0 0 0" />
      <geometry>
        <mesh
          filename="package://spryped_urdf_rev05/meshes/right toe.STL" />
      </geometry>
      <material
        name="">
        <color
          rgba="1 1 1 1" />
      </material>
    </visual>
    <collision>
      <origin
        xyz="0 0 0"
        rpy="0 0 0" />
      <geometry>
        <mesh
          filename="package://spryped_urdf_rev05/meshes/right toe.STL" />
      </geometry>
    </collision>
  </link>
  <joint
    name="8"
    type="revolute">
    <origin
      xyz="0.105453933614102 -0.0339000000000002 -0.488752972251863"
      rpy="0 0 0" />
    <parent
      link="right tarsometatarsus" />
    <child
      link="right toe" />
    <axis
      xyz="0 -1 0" />
    <limit
      lower="-3.14"
      upper="3.14"
      effort="0"
      velocity="0" />
  </joint>
</robot>